Workbook

Sheet Overview
A1: Archetype – Data Warehouse Rebuild (Phase 1) · Detailed Project Plan & Phase KPIs
A2: Kế hoạch chi tiết & KPI từng giai đoạn · TMA Innovation · Draft for Archetype review
A4: Project start (W1 Monday) · Ngày bắt đầu (thứ 2 tuần 1) | B4: =DATE(2026,10,5) -> 46300 | C4: Input – all dates in the plan derive from this cell / Ô nhập – mọi ngày trong kế hoạch tính từ ô này
A5: Contract end · Ngày kết thúc HĐ | B5: =DATE(2027,4,9) -> 46486 | C5: Per contract (as updated) / Theo hợp đồng
A6: Warranty end · Kết thúc bảo hành | B6: =DATE(2027,7,6) -> 46574 | C6: 3 months after contract end / 3 tháng sau kết thúc HĐ
A7: Plan version · Phiên bản | B7: v0.1 – 08/10/2026 | C7: To be approved by Group IT/IS Director (target W3) / Chờ phê duyệt (mục tiêu W3)
A9: Phase summary · Tổng hợp giai đoạn
A10: Phase · Giai đoạn | B10: Name · Tên | C10: Start wk | D10: End wk | E10: Start date | F10: End date | G10: Milestone | H10: % Complete (avg of tasks)
A11: P1 | B11: Consult, analyze, design & platform setup · Tư vấn, phân tích, thiết kế & dựng nền tảng | C11: =_xlfn.MINIFS(WBS!$H:$H,WBS!$B:$B,A11,WBS!$C:$C,"Task") -> 1 | D11: =_xlfn.MAXIFS(WBS!$I:$I,WBS!$B:$B,A11,WBS!$C:$C,"Task") -> 5 | E11: =$B$4+7*(C11-1) -> 46300 | F11: =$B$4+7*(D11-1)+4 -> 46332 | G11: M1 – Platform baseline (W5) | H11: =IFERROR(AVERAGEIFS(WBS!$N:$N,WBS!$B:$B,A11,WBS!$C:$C,"Task"),0) -> 0
A12: P2 | B12: Timesheet E2E · Luồng Timesheet đầu-cuối | C12: =_xlfn.MINIFS(WBS!$H:$H,WBS!$B:$B,A12,WBS!$C:$C,"Task") -> 5 | D12: =_xlfn.MAXIFS(WBS!$I:$I,WBS!$B:$B,A12,WBS!$C:$C,"Task") -> 6 | E12: =$B$4+7*(C12-1) -> 46328 | F12: =$B$4+7*(D12-1)+4 -> 46339 | G12: M2 – Timesheet E2E (W6) | H12: =IFERROR(AVERAGEIFS(WBS!$N:$N,WBS!$B:$B,A12,WBS!$C:$C,"Task"),0) -> 0
A13: P3 | B13: Guided build-out & parallel run · Nhân rộng có hướng dẫn & chạy song song | C13: =_xlfn.MINIFS(WBS!$H:$H,WBS!$B:$B,A13,WBS!$C:$C,"Task") -> 7 | D13: =_xlfn.MAXIFS(WBS!$I:$I,WBS!$B:$B,A13,WBS!$C:$C,"Task") -> 13 | E13: =$B$4+7*(C13-1) -> 46342 | F13: =$B$4+7*(D13-1)+4 -> 46388 | G13: M3 – Dashboards & pipelines accepted (W13) | H13: =IFERROR(AVERAGEIFS(WBS!$N:$N,WBS!$B:$B,A13,WBS!$C:$C,"Task"),0) -> 0
A14: P4 | B14: pgvector use case, handover & go-live · PoC pgvector, bàn giao & go-live | C14: =_xlfn.MINIFS(WBS!$H:$H,WBS!$B:$B,A14,WBS!$C:$C,"Task") -> 13 | D14: =_xlfn.MAXIFS(WBS!$I:$I,WBS!$B:$B,A14,WBS!$C:$C,"Task") -> 14 | E14: =$B$4+7*(C14-1) -> 46384 | F14: =$B$4+7*(D14-1)+4 -> 46395 | G14: M4 – Phase 1 delivery accepted (W14) | H14: =IFERROR(AVERAGEIFS(WBS!$N:$N,WBS!$B:$B,A14,WBS!$C:$C,"Task"),0) -> 0
A15: P5 | B15: Hypercare · Hỗ trợ sau go-live | C15: =_xlfn.MINIFS(WBS!$H:$H,WBS!$B:$B,A15,WBS!$C:$C,"Task") -> 15 | D15: =_xlfn.MAXIFS(WBS!$I:$I,WBS!$B:$B,A15,WBS!$C:$C,"Task") -> 24 | E15: =$B$4+7*(C15-1) -> 46398 | F15: =$B$4+7*(D15-1)+4 -> 46465 | G15: M5 – Hypercare closed (W24) | H15: =IFERROR(AVERAGEIFS(WBS!$N:$N,WBS!$B:$B,A15,WBS!$C:$C,"Task"),0) -> 0
A17: How to use · Cách sử dụng
A18: • Yellow cells are inputs: project start date, task Status and % Complete. Ô vàng là ô nhập: ngày bắt đầu, Status và % hoàn thành.
A19: • Start/End week drive the dates and the Gantt bars automatically. Tuần bắt đầu/kết thúc tự sinh ngày và thanh Gantt.
A20: • Each milestone must be accepted (signed minutes) before the next phase starts (contract Art. 8.6). Mỗi mốc phải được nghiệm thu trước khi sang giai đoạn sau (Điều 8.6 HĐ).
A21: • Dates are calendar weeks; public holidays (01/01/2027, Lunar New Year ~06/02/2027) are not deducted – the contract extends the term accordingly. Ngày tính theo tuần lịch, chưa trừ lễ Tết; HĐ cho phép gia hạn tương ứng.
A22: • KPI targets marked "TBC with SME" need confirmation from Archetype data owners during W1–W3. KPI ghi "TBC with SME" cần SME Archetype xác nhận trong W1–W3.

Sheet WBS
A1: Work Breakdown Structure & Timeline · Cấu trúc công việc & tiến độ
A2: Owner/Support: TMA = TMA team · ARC = Archetype · DIR = Group IT/IS Director · BI = Archetype BI · DEV = Archetype DevOps · SME = data owners. Yellow = input.
A4: ID | B4: Phase | C4: Type | D4: Task (EN) | E4: Công việc (VI) | F4: Owner | G4: Support | H4: Start wk | I4: End wk | J4: Start date | K4: End date | L4: Deliverable / Output · Kết quả | M4: Status | N4: % Complete | O4: W1 | P4: W2 | Q4: W3 | R4: W4 | S4: W5 | T4: W6 | U4: W7 | V4: W8 | W4: W9 | X4: W10 | Y4: W11 | Z4: W12 | AA4: W13 | AB4: W14 | AC4: W15 | AD4: W16 | AE4: W17 | AF4: W18 | AG4: W19 | AH4: W20 | AI4: W21 | AJ4: W22 | AK4: W23 | AL4: W24
O5: =Overview!$B$4+7*(1-1) -> 46300 | P5: =Overview!$B$4+7*(2-1) -> 46307 | Q5: =Overview!$B$4+7*(3-1) -> 46314 | R5: =Overview!$B$4+7*(4-1) -> 46321 | S5: =Overview!$B$4+7*(5-1) -> 46328 | T5: =Overview!$B$4+7*(6-1) -> 46335 | U5: =Overview!$B$4+7*(7-1) -> 46342 | V5: =Overview!$B$4+7*(8-1) -> 46349 | W5: =Overview!$B$4+7*(9-1) -> 46356 | X5: =Overview!$B$4+7*(10-1) -> 46363 | Y5: =Overview!$B$4+7*(11-1) -> 46370 | Z5: =Overview!$B$4+7*(12-1) -> 46377 | AA5: =Overview!$B$4+7*(13-1) -> 46384 | AB5: =Overview!$B$4+7*(14-1) -> 46391 | AC5: =Overview!$B$4+7*(15-1) -> 46398 | AD5: =Overview!$B$4+7*(16-1) -> 46405 | AE5: =Overview!$B$4+7*(17-1) -> 46412 | AF5: =Overview!$B$4+7*(18-1) -> 46419 | AG5: =Overview!$B$4+7*(19-1) -> 46426 | AH5: =Overview!$B$4+7*(20-1) -> 46433 | AI5: =Overview!$B$4+7*(21-1) -> 46440 | AJ5: =Overview!$B$4+7*(22-1) -> 46447 | AK5: =Overview!$B$4+7*(23-1) -> 46454 | AL5: =Overview!$B$4+7*(24-1) -> 46461
A6: P1 | B6: P1 | C6: Phase | D6: Consult, analyze, design & platform setup | E6: Tư vấn, phân tích, thiết kế & dựng nền tảng | F6: TMA | G6: ARC | H6: =_xlfn.MINIFS($H:$H,$B:$B,B6,$C:$C,"<>Phase") -> 1 | I6: =_xlfn.MAXIFS($I:$I,$B:$B,B6,$C:$C,"<>Phase") -> 5 | J6: =Overview!$B$4+7*(H6-1) -> 46300 | K6: =Overview!$B$4+7*(I6-1)+4 -> 46332 | L6: Platform baseline | M6: =IF(N6>=1,"Done",IF(N6>0,"In progress","Not started")) -> Not started | N6: =IFERROR(AVERAGEIFS($N:$N,$B:$B,B6,$C:$C,"Task"),0) -> 0
A7: 1.1 | B7: P1 | C7: Task | D7: Kick-off; confirm team, RACI, communication & tools | E7: Kick-off; chốt nhân sự, RACI, kênh trao đổi & công cụ | F7: TMA | G7: ARC | H7: 1 | I7: 1 | J7: =Overview!$B$4+7*(H7-1) -> 46300 | K7: =Overview!$B$4+7*(I7-1)+4 -> 46304 | L7: Kick-off deck, minutes | M7: Not started | N7: 0
A8: 1.2 | B8: P1 | C8: Task | D8: Provide inputs: Azure access, service accounts, SSIS packages, PBIX, table inventory, sample data | E8: Cung cấp đầu vào: quyền Azure, service account, SSIS, PBIX, danh sách bảng, sample data | F8: ARC | G8: TMA | H8: 1 | I8: 1 | J8: =Overview!$B$4+7*(H8-1) -> 46300 | K8: =Overview!$B$4+7*(I8-1)+4 -> 46304 | L8: Input checklist completed | M8: Not started | N8: 0
A9: 1.3 | B9: P1 | C9: Task | D9: Hand over full Timesheet dashboard requirements | E9: Bàn giao đầy đủ yêu cầu dashboard Timesheet | F9: BI | G9: TMA | H9: 1 | I9: 1 | J9: =Overview!$B$4+7*(H9-1) -> 46300 | K9: =Overview!$B$4+7*(I9-1)+4 -> 46304 | L9: Timesheet requirement spec | M9: Not started | N9: 0
A10: 1.4 | B10: P1 | C10: Task | D10: Detailed project plan & phase KPIs – draft, review, approve | E10: Kế hoạch chi tiết & KPI giai đoạn – soạn, review, phê duyệt | F10: TMA | G10: DIR | H10: 1 | I10: 3 | J10: =Overview!$B$4+7*(H10-1) -> 46300 | K10: =Overview!$B$4+7*(I10-1)+4 -> 46318 | L10: Approved plan (this workbook) | M10: Not started | N10: 0
A11: 1.5 | B11: P1 | C11: Task | D11: Current-state assessment: sources, SSIS logic, 5 dashboards, table prioritization | E11: Khảo sát hiện trạng: nguồn, logic SSIS, 5 dashboard, ưu tiên bảng | F11: TMA | G11: BI, SME | H11: 1 | I11: 2 | J11: =Overview!$B$4+7*(H11-1) -> 46300 | K11: =Overview!$B$4+7*(I11-1)+4 -> 46311 | L11: Assessment report, prioritized table list | M11: Not started | N11: 0
A12: 1.6 | B12: P1 | C12: Task | D12: Legacy connector PoC: SQL Server 2008 TLS/driver via Self-hosted IR | E12: PoC kết nối SQL Server 2008 (TLS/driver) qua Self-hosted IR | F12: TMA | G12: DEV | H12: 2 | I12: 2 | J12: =Overview!$B$4+7*(H12-1) -> 46307 | K12: =Overview!$B$4+7*(I12-1)+4 -> 46311 | L12: PoC result; CR if limits found | M12: Not started | N12: 0
A13: 1.7 | B13: P1 | C13: Task | D13: Confirm open items: history scope, NAV table count, integration directions | E13: Chốt vấn đề mở: phạm vi lịch sử, số bảng NAV, hướng 4 tích hợp | F13: ARC | G13: TMA | H13: 1 | I13: 2 | J13: =Overview!$B$4+7*(H13-1) -> 46300 | K13: =Overview!$B$4+7*(I13-1)+4 -> 46311 | L13: Decision log | M13: Not started | N13: 0
A14: 1.8 | B14: P1 | C14: Task | D14: Provision Azure Dev/UAT/Prod: PostgreSQL, Blob, ADF, Container Apps, Key Vault, Monitor, VPN, Windows VM (SHIR) | E14: Dựng Azure Dev/UAT/Prod: PostgreSQL, Blob, ADF, Container Apps, Key Vault, Monitor, VPN, Windows VM (SHIR) | F14: DEV | G14: TMA | H14: 2 | I14: 3 | J14: =Overview!$B$4+7*(H14-1) -> 46307 | K14: =Overview!$B$4+7*(I14-1)+4 -> 46318 | L14: 3 environments ready | M14: Not started | N14: 0
A15: 1.9 | B15: P1 | C15: Task | D15: HLA/LLD: architecture, data model (layers, naming, conformed dims), security & operations design | E15: HLA/LLD: kiến trúc, data model (lớp, quy ước, dim dùng chung), bảo mật & vận hành | F15: TMA | G15: DEV, BI | H15: 2 | I15: 4 | J15: =Overview!$B$4+7*(H15-1) -> 46307 | K15: =Overview!$B$4+7*(I15-1)+4 -> 46325 | L15: HLA/LLD document (approved) | M15: Not started | N15: 0
A16: 1.10 | B16: P1 | C16: Task | D16: Platform baseline: parameterized ADF ingestion (watermark, retry, alert), dbt project, Elementary, Git, CI | E16: Nền tảng cơ sở: ADF tham số hóa (watermark, retry, cảnh báo), dbt, Elementary, Git, CI | F16: TMA | G16: DEV | H16: 3 | I16: 5 | J16: =Overview!$B$4+7*(H16-1) -> 46314 | K16: =Overview!$B$4+7*(I16-1)+4 -> 46332 | L16: Running framework in Dev/UAT | M16: Not started | N16: 0
A17: 1.11 | B17: P1 | C17: Task | D17: Security baseline: Entra ID SSO, RLS framework, masking views, Key Vault secrets | E17: Bảo mật nền: SSO Entra ID, khung RLS, view masking, secrets Key Vault | F17: TMA | G17: DEV | H17: 4 | I17: 5 | J17: =Overview!$B$4+7*(H17-1) -> 46321 | K17: =Overview!$B$4+7*(I17-1)+4 -> 46332 | L17: Security test cases passed | M17: Not started | N17: 0
A18: 1.12 | B18: P1 | C18: Task | D18: Training #1: platform, ADF & dbt fundamentals (workshop) | E18: Đào tạo #1: nền tảng, ADF & dbt cơ bản (workshop) | F18: TMA | G18: BI, DEV | H18: 5 | I18: 5 | J18: =Overview!$B$4+7*(H18-1) -> 46328 | K18: =Overview!$B$4+7*(I18-1)+4 -> 46332 | L18: Training material, attendance | M18: Not started | N18: 0
A19: M1 | B19: P1 | C19: Milestone | D19: M1 – Platform baseline accepted | E19: M1 – Nghiệm thu nền tảng cơ sở | F19: DIR | G19: TMA | H19: 5 | I19: 5 | J19: =Overview!$B$4+7*(H19-1) -> 46328 | K19: =Overview!$B$4+7*(I19-1)+4 -> 46332 | L19: Signed acceptance minutes | M19: Not started | N19: 0
A20: P2 | B20: P2 | C20: Phase | D20: Timesheet E2E | E20: Luồng Timesheet đầu-cuối | F20: TMA | G20: BI | H20: =_xlfn.MINIFS($H:$H,$B:$B,B20,$C:$C,"<>Phase") -> 5 | I20: =_xlfn.MAXIFS($I:$I,$B:$B,B20,$C:$C,"<>Phase") -> 6 | J20: =Overview!$B$4+7*(H20-1) -> 46328 | K20: =Overview!$B$4+7*(I20-1)+4 -> 46339 | L20: Reference pipeline | M20: =IF(N20>=1,"Done",IF(N20>0,"In progress","Not started")) -> Not started | N20: =IFERROR(AVERAGEIFS($N:$N,$B:$B,B20,$C:$C,"Task"),0) -> 0
A21: 2.1 | B21: P2 | C21: Task | D21: Ingest Timesheet sources (≤ 10 tables) into RAW | E21: Nạp nguồn Timesheet (≤ 10 bảng) vào RAW | F21: TMA | G21: DEV | H21: 5 | I21: 5 | J21: =Overview!$B$4+7*(H21-1) -> 46328 | K21: =Overview!$B$4+7*(I21-1)+4 -> 46332 | L21: RAW tables loaded hourly | M21: Not started | N21: 0
A22: 2.2 | B22: P2 | C22: Task | D22: dbt models staging → dwh → mart (≤ 20 models), Timesheet fact & selected dims | E22: dbt model staging → dwh → mart (≤ 20 model), fact Timesheet & dim chọn lọc | F22: TMA | G22: SME | H22: 5 | I22: 6 | J22: =Overview!$B$4+7*(H22-1) -> 46328 | K22: =Overview!$B$4+7*(I22-1)+4 -> 46339 | L22: Timesheet mart | M22: Not started | N22: 0
A23: 2.3 | B23: P2 | C23: Task | D23: Elementary tests & reconciliation vs. legacy (≤ 6 acceptance KPIs) | E23: Test Elementary & đối soát với hệ thống cũ (≤ 6 KPI nghiệm thu) | F23: TMA | G23: BI, SME | H23: 6 | I23: 6 | J23: =Overview!$B$4+7*(H23-1) -> 46335 | K23: =Overview!$B$4+7*(I23-1)+4 -> 46339 | L23: Reconciliation report | M23: Not started | N23: 0
A24: 2.4 | B24: P2 | C24: Task | D24: Build Timesheet dashboard on MART | E24: Xây dashboard Timesheet trên MART | F24: BI | G24: TMA | H24: 5 | I24: 6 | J24: =Overview!$B$4+7*(H24-1) -> 46328 | K24: =Overview!$B$4+7*(I24-1)+4 -> 46339 | L24: Timesheet dashboard | M24: Not started | N24: 0
A25: 2.5 | B25: P2 | C25: Task | D25: Training #2: pair-working walkthrough of the reference pipeline | E25: Đào tạo #2: pair-working trên pipeline mẫu | F25: TMA | G25: BI | H25: 6 | I25: 6 | J25: =Overview!$B$4+7*(H25-1) -> 46335 | K25: =Overview!$B$4+7*(I25-1)+4 -> 46339 | L25: Reference pipeline guide | M25: Not started | N25: 0
A26: M2 | B26: P2 | C26: Milestone | D26: M2 – Timesheet E2E accepted | E26: M2 – Nghiệm thu luồng Timesheet | F26: DIR | G26: TMA | H26: 6 | I26: 6 | J26: =Overview!$B$4+7*(H26-1) -> 46335 | K26: =Overview!$B$4+7*(I26-1)+4 -> 46339 | L26: Signed acceptance minutes | M26: Not started | N26: 0
A27: P3 | B27: P3 | C27: Phase | D27: Guided build-out & parallel run | E27: Nhân rộng có hướng dẫn & chạy song song | F27: BI | G27: TMA | H27: =_xlfn.MINIFS($H:$H,$B:$B,B27,$C:$C,"<>Phase") -> 7 | I27: =_xlfn.MAXIFS($I:$I,$B:$B,B27,$C:$C,"<>Phase") -> 13 | J27: =Overview!$B$4+7*(H27-1) -> 46342 | K27: =Overview!$B$4+7*(I27-1)+4 -> 46388 | L27: 6–7 pipelines, 4 integrations | M27: =IF(N27>=1,"Done",IF(N27>0,"In progress","Not started")) -> Not started | N27: =IFERROR(AVERAGEIFS($N:$N,$B:$B,B27,$C:$C,"Task"),0) -> 0
A28: 3.1 | B28: P3 | C28: Task | D28: Prioritize & plan remaining 5–6 pipelines/dashboards | E28: Ưu tiên & lập kế hoạch 5–6 pipeline/dashboard còn lại | F28: BI | G28: TMA, DIR | H28: 7 | I28: 7 | J28: =Overview!$B$4+7*(H28-1) -> 46342 | K28: =Overview!$B$4+7*(I28-1)+4 -> 46346 | L28: Build-out backlog | M28: Not started | N28: 0
A29: 3.2 | B29: P3 | C29: Task | D29: Finance pipeline & dashboard | E29: Pipeline & dashboard Finance | F29: BI | G29: TMA | H29: 7 | I29: 9 | J29: =Overview!$B$4+7*(H29-1) -> 46342 | K29: =Overview!$B$4+7*(I29-1)+4 -> 46360 | L29: Finance mart & dashboard | M29: Not started | N29: 0
A30: 3.3 | B30: P3 | C30: Task | D30: Contract (Project) pipeline & dashboard | E30: Pipeline & dashboard Contract (Project) | F30: BI | G30: TMA | H30: 8 | I30: 10 | J30: =Overview!$B$4+7*(H30-1) -> 46349 | K30: =Overview!$B$4+7*(I30-1)+4 -> 46367 | L30: Contract mart & dashboard | M30: Not started | N30: 0
A31: 3.4 | B31: P3 | C31: Task | D31: HR pipeline & dashboard | E31: Pipeline & dashboard HR | F31: BI | G31: TMA | H31: 9 | I31: 11 | J31: =Overview!$B$4+7*(H31-1) -> 46356 | K31: =Overview!$B$4+7*(I31-1)+4 -> 46374 | L31: HR mart & dashboard | M31: Not started | N31: 0
A32: 3.5 | B32: P3 | C32: Task | D32: MD (Managing Director) pipeline & dashboard | E32: Pipeline & dashboard MD | F32: BI | G32: TMA | H32: 10 | I32: 12 | J32: =Overview!$B$4+7*(H32-1) -> 46363 | K32: =Overview!$B$4+7*(I32-1)+4 -> 46381 | L32: MD mart & dashboard | M32: Not started | N32: 0
A33: 3.6 | B33: P3 | C33: Task | D33: Additional pipeline(s) to reach 6–7 in total | E33: Pipeline bổ sung để đủ 6–7 | F33: BI | G33: TMA | H33: 11 | I33: 13 | J33: =Overview!$B$4+7*(H33-1) -> 46370 | K33: =Overview!$B$4+7*(I33-1)+4 -> 46388 | L33: Additional mart(s) | M33: Not started | N33: 0
A34: 3.7 | B34: P3 | C34: Task | D34: Rebuild 4 integrations (Timesheet, Budget, Contract, Employee) in ADF | E34: Viết lại 4 tích hợp (Timesheet, Budget, Contract, Employee) bằng ADF | F34: TMA | G34: DEV, SME | H34: 7 | I34: 12 | J34: =Overview!$B$4+7*(H34-1) -> 46342 | K34: =Overview!$B$4+7*(I34-1)+4 -> 46381 | L34: 4 integration pipelines | M34: Not started | N34: 0
A35: 3.8 | B35: P3 | C35: Task | D35: Historical data load (scope as agreed in 1.7) | E35: Nạp dữ liệu lịch sử (phạm vi theo 1.7) | F35: TMA | G35: DEV | H35: 7 | I35: 10 | J35: =Overview!$B$4+7*(H35-1) -> 46342 | K35: =Overview!$B$4+7*(I35-1)+4 -> 46367 | L35: History loaded & reconciled | M35: Not started | N35: 0
A36: 3.9 | B36: P3 | C36: Task | D36: Parallel run & reconciliation: legacy vs. new DWH | E36: Chạy song song & đối soát DWH cũ vs. mới | F36: BI | G36: TMA, SME | H36: 7 | I36: 13 | J36: =Overview!$B$4+7*(H36-1) -> 46342 | K36: =Overview!$B$4+7*(I36-1)+4 -> 46388 | L36: Weekly reconciliation report | M36: Not started | N36: 0
A37: 3.10 | B37: P3 | C37: Task | D37: Weekly pair-working clinics & code reviews | E37: Buổi pair-working & review code hằng tuần | F37: TMA | G37: BI | H37: 7 | I37: 13 | J37: =Overview!$B$4+7*(H37-1) -> 46342 | K37: =Overview!$B$4+7*(I37-1)+4 -> 46388 | L37: Review log | M37: Not started | N37: 0
A38: 3.11 | B38: P3 | C38: Task | D38: UAT by Finance & Accounting and HR | E38: UAT bởi Finance & Accounting và HR | F38: SME | G38: BI, TMA | H38: 11 | I38: 13 | J38: =Overview!$B$4+7*(H38-1) -> 46370 | K38: =Overview!$B$4+7*(I38-1)+4 -> 46388 | L38: UAT sign-off, defect log | M38: Not started | N38: 0
A39: M3 | B39: P3 | C39: Milestone | D39: M3 – Pipelines/dashboards accepted; go/no-go for decommission | E39: M3 – Nghiệm thu pipeline/dashboard; quyết định ngưng DWH cũ | F39: DIR | G39: TMA, BI | H39: 13 | I39: 13 | J39: =Overview!$B$4+7*(H39-1) -> 46384 | K39: =Overview!$B$4+7*(I39-1)+4 -> 46388 | L39: Signed acceptance minutes | M39: Not started | N39: 0
A40: P4 | B40: P4 | C40: Phase | D40: pgvector use case, handover & go-live | E40: PoC pgvector, bàn giao & go-live | F40: TMA | G40: ARC | H40: =_xlfn.MINIFS($H:$H,$B:$B,B40,$C:$C,"<>Phase") -> 13 | I40: =_xlfn.MAXIFS($I:$I,$B:$B,B40,$C:$C,"<>Phase") -> 14 | J40: =Overview!$B$4+7*(H40-1) -> 46384 | K40: =Overview!$B$4+7*(I40-1)+4 -> 46395 | L40: Phase 1 delivery | M40: =IF(N40>=1,"Done",IF(N40>0,"In progress","Not started")) -> Not started | N40: =IFERROR(AVERAGEIFS($N:$N,$B:$B,B40,$C:$C,"Task"),0) -> 0
A41: 4.1 | B41: P4 | C41: Task | D41: pgvector + text-to-SQL PoC: metadata embeddings, LLM, guardrails, Metabase integration | E41: PoC pgvector + text-to-SQL: embedding metadata, LLM, guardrail, tích hợp Metabase | F41: TMA | G41: BI | H41: 13 | I41: 14 | J41: =Overview!$B$4+7*(H41-1) -> 46384 | K41: =Overview!$B$4+7*(I41-1)+4 -> 46395 | L41: Working PoC + test question set | M41: Not started | N41: 0
...

Sheet Phase KPIs
A1: Phase KPIs & acceptance criteria · KPI & tiêu chí nghiệm thu từng giai đoạn
A2: Targets marked "TBC with SME" to be confirmed by Archetype data owners in W1–W3. Actual & Met? are filled at each milestone review.
A4: Phase | B4: KPI (EN) | C4: KPI (VI) | D4: Target · Mục tiêu | E4: Measurement · Cách đo | F4: Evidence · Bằng chứng | G4: Owner | H4: Due wk | I4: Actual · Thực tế | J4: Met? (Y/N)
A5: P1 | B5: Detailed plan & phase KPIs approved | C5: Kế hoạch & KPI được phê duyệt | D5: Signed by W3 (21/10/2026) | E5: Approval email / minutes | F5: Approved workbook | G5: TMA / DIR | H5: 3
A6: P1 | B6: Project inputs received | C6: Đầu vào dự án đã nhận | D6: ≥ 90% of input checklist by end of W1; 100% by W2 | E6: Checklist completion | F6: Input checklist | G6: ARC | H6: 2
A7: P1 | B7: Source connectivity (legacy connector PoC) | C7: Kết nối nguồn (PoC legacy) | D7: 100% sources reachable via SHIR: 15 NAV DBs, MySQL, PostgreSQL 18, files | E7: Test extraction per source | F7: PoC report | G7: TMA / DEV | H7: 2
A8: P1 | B8: Environments provisioned | C8: Môi trường đã dựng | D8: Dev, UAT, Prod ready (3/3) | E8: Environment checklist | F8: Azure resource inventory | G8: DEV | H8: 3
A9: P1 | B9: HLA/LLD approved | C9: HLA/LLD được phê duyệt | D9: Approved by W4 | E9: Review sign-off | F9: HLA/LLD document | G9: TMA / DIR | H9: 4
A10: P1 | B10: Platform baseline stability | C10: Độ ổn định nền tảng | D10: Sample hourly pipeline ≥ 95% successful runs over 5 consecutive working days | E10: ADF run history | F10: Azure Monitor export | G10: TMA | H10: 5
A11: P1 | B11: Security baseline | C11: Bảo mật nền | D11: 100% RLS & masking test cases passed; SSO working | E11: Security test cases | F11: Test results | G11: TMA | H11: 5
A12: P2 | B12: Timesheet E2E delivered | C12: Hoàn thành luồng Timesheet | D12: Live in UAT/Prod by end of W6 | E12: Milestone review | F12: Demo + acceptance minutes | G12: TMA / BI | H12: 6
A13: P2 | B13: Data freshness | C13: Độ trễ dữ liệu | D13: ≤ 60 min from source change to MART | E13: Load timestamps vs. source | F13: Freshness test (Elementary) | G13: TMA | H13: 6
A14: P2 | B14: Reconciliation vs. legacy | C14: Đối soát với hệ thống cũ | D14: 100% of ≤ 6 acceptance KPIs within agreed tolerance (TBC with SME) | E14: KPI comparison legacy vs. new | F14: Reconciliation report | G14: BI / SME | H14: 6
A15: P2 | B15: Data quality tests | C15: Kiểm thử chất lượng dữ liệu | D15: 100% critical Elementary tests passing | E15: Elementary report | F15: DQ report | G15: TMA | H15: 6
A16: P2 | B16: Dashboard performance | C16: Hiệu năng dashboard | D16: Timesheet dashboard opens ≤ 30 s | E16: Timed load test | F16: Test log | G16: BI | H16: 6
... A33: P5 | B33: Final acceptance | C33: Nghiệm thu cuối | D33: Signed by end of W24 | E33: Acceptance minutes | F33: Final acceptance minutes | G33: DIR | H33: 24
A35: KPI scorecard · Tổng hợp
A36: Phase | B36: # KPIs | C36: # Met (Y) | D36: % Met
A37: P1 | B37: =COUNTIF($A$5:$A$33,A37) -> 7 | C37: =COUNTIFS($A$5:$A$33,A37,$J$5:$J$33,"Y") -> 0 | D37: =IF(B37=0,0,C37/B37) -> 0
A38: P2 | B38: =COUNTIF($A$5:$A$33,A38) -> 5 | C38: =COUNTIFS($A$5:$A$33,A38,$J$5:$J$33,"Y") -> 0 | D38: =IF(B38=0,0,C38/B38) -> 0
A39: P3 | B39: =COUNTIF($A$5:$A$33,A39) -> 7 | C39: =COUNTIFS($A$5:$A$33,A39,$J$5:$J$33,"Y") -> 0 | D39: =IF(B39=0,0,C39/B39) -> 0
A40: P4 | B40: =COUNTIF($A$5:$A$33,A40) -> 5 | C40: =COUNTIFS($A$5:$A$33,A40,$J$5:$J$33,"Y") -> 0 | D40: =IF(B40=0,0,C40/B40) -> 0
A41: P5 | B41: =COUNTIF($A$5:$A$33,A41) -> 5 | C41: =COUNTIFS($A$5:$A$33,A41,$J$5:$J$33,"Y") -> 0 | D41: =IF(B41=0,0,C41/B41) -> 0

Sheet Milestones
A1: Milestones & acceptance · Mốc & nghiệm thu
A2: Each milestone must be accepted before moving to the next stage (contract Art. 8.6). Client feedback within 15 working days of handover notice (Art. 8.2).
A4: ID | B4: Milestone (EN) | C4: Mốc (VI) | D4: Week | E4: Target date | F4: Acceptance criteria · Tiêu chí | G4: Sign-off | H4: Status | I4: Actual date
A5: M0 | B5: Kick-off & contract start | C5: Kick-off & bắt đầu hợp đồng | D5: 1 | E5: =Overview!$B$4+7*(D5-1)+4 -> 46304 | F5: Kick-off held; payment milestone 1 (50%) invoiced | G5: TMA / DIR | H5: Planned
A6: M1 | B6: Platform baseline | C6: Nền tảng cơ sở | D6: 5 | E6: =Overview!$B$4+7*(D6-1)+4 -> 46332 | F6: All P1 KPIs met (Phase KPIs sheet) | G6: DIR | H6: Planned
A7: M2 | B7: Timesheet E2E | C7: Luồng Timesheet đầu-cuối | D7: 6 | E7: =Overview!$B$4+7*(D7-1)+4 -> 46339 | F7: All P2 KPIs met | G7: DIR | H7: Planned
A8: M3 | B8: Pipelines/dashboards accepted; go/no-go for decommission | C8: Nghiệm thu pipeline/dashboard; quyết định ngưng DWH cũ | D8: 13 | E8: =Overview!$B$4+7*(D8-1)+4 -> 46388 | F8: All P3 KPIs met; UAT signed | G8: DIR | H8: Planned
A9: M4 | B9: Phase 1 delivery accepted (go-live) | C9: Nghiệm thu bàn giao Phase 1 (go-live) | D9: 14 | E9: =Overview!$B$4+7*(D9-1)+4 -> 46395 | F9: All P4 KPIs met; 5 deliverables handed over | G9: DIR | H9: Planned
A10: M5 | B10: Hypercare closed; final acceptance | C10: Kết thúc hypercare; nghiệm thu cuối | D10: 24 | E10: =Overview!$B$4+7*(D10-1)+4 -> 46465 | F10: All P5 KPIs met | G10: DIR | H10: Planned
A11: W | B11: Warranty end | C11: Kết thúc bảo hành | D11: — | E11: =Overview!$B$6 -> 46574 | F11: Defects in scope fixed free of charge until this date | G11: DIR | H11: Planned
A12: PAY2 | B12: Payment milestone 2 (50%) | C12: Thanh toán đợt 2 (50%) | D12: — | E12: =Overview!$B$6+30 -> 46604 | F12: Within 30 days after final acceptance & warranty completion record (Art. 10) | G12: DIR | H12: Planned

Sheet RAID
A1: RAID log · Rủi ro, Giả định, Vấn đề, Phụ thuộc
A2: R = Risk (rủi ro) · A = Assumption (giả định) · I = Issue (vấn đề) · D = Dependency (phụ thuộc). Updated weekly with the status report.
A4: ID | B4: Type | C4: Description (EN) | D4: Mô tả (VI) | E4: Impact | F4: Likelihood | G4: Mitigation / Action | H4: Owner | I4: Due wk | J4: Status
A5: R1 | B5: Risk | C5: SQL Server 2008 TLS/driver incompatible with Self-hosted IR | D5: SQL Server 2008 không tương thích TLS/driver với SHIR | E5: High | F5: Medium | G5: PoC in W2; fallback driver/TLS settings; CR if limits remain | H5: TMA | I5: 2 | J5: Open
A6: R2 | B6: Risk | C6: Master data (entity, office, country) not standardized until 11/2026 | D6: Master data chưa chuẩn hóa xong đến 11/2026 | E6: High | F6: High | G6: Use mapping tables & default codes; reprocess once finalized | H6: SME | I6: 8 | J6: Open
A7: R3 | B7: Risk | C7: Historical load scope unclear (full history vs. 2 years); Timesheet 1.5M rows | D7: Phạm vi dữ liệu lịch sử chưa rõ; Timesheet 1.5 triệu dòng | E7: Medium | F7: Medium | G7: Decide in 1.7; partition & summarize older years | H7: ARC | I7: 2 | J7: Open
A8: R4 | B8: Risk | C8: SME availability for KPI/mapping confirmation | D8: SME không kịp xác nhận KPI/mapping | E8: High | F8: Medium | G8: 2-working-day response rule; escalate to Director | H8: DIR | I8: 24 | J8: Open
A9: R5 | B9: Risk | C9: Archetype BI ramp-up on dbt/ADF slower than planned | D9: Đội BI làm quen dbt/ADF chậm hơn kế hoạch | E9: Medium | F9: Medium | G9: Training #1–#2, weekly clinics, reference pipeline | H9: TMA | I9: 13 | J9: Open
A10: A1 | B10: Assumption | C10: Archetype provisions Azure services, VPN and Windows VM by W3 | D10: Archetype cấp dịch vụ Azure, VPN, Windows VM trước W3 | E10: High | F10: — | G10: Track in 1.8 | H10: DEV | I10: 3 | J10: Open
A11: A2 | B11: Assumption | C11: DWH is read-only; hourly batch, no CDC in Phase 1 | D11: DWH chỉ đọc; batch theo giờ, không CDC | E11: Medium | F11: — | G11: Confirmed in contract assumptions | H11: TMA | I11: 1 | J11: Closed
A12: D1 | B12: Dependency | C12: Timesheet requirements from Archetype BI in W1 | D12: Yêu cầu Timesheet từ BI Archetype trong W1 | E12: High | F12: — | G12: Blocks P2 start | H12: BI | I12: 1 | J12: Open
A13: D2 | B13: Dependency | C13: Contract wording update for tech stack (ADF + dbt, no Airflow/dlt) | D13: Cập nhật câu chữ HĐ về stack (ADF + dbt, bỏ Airflow/dlt) | E13: Medium | F13: — | G13: Contract amendment / appendix | H13: TMA / DIR | I13: 3 | J13: Closed
A14: I1 | B14: Issue | C14: (example) Service account for MySQL not yet created | D14: (ví dụ) Chưa có service account MySQL | E14: Medium | F14: — | G14: Request raised to DevOps | H14: DEV | I14: 2 | J14: Open
